#VRML_SIM R2025a utf8

EXTERNPROTO "https://raw.githubusercontent.com/cyberbotics/webots/R2025a/projects/objects/backgrounds/protos/TexturedBackground.proto"
EXTERNPROTO "https://raw.githubusercontent.com/cyberbotics/webots/R2025a/projects/objects/backgrounds/protos/TexturedBackgroundLight.proto"
EXTERNPROTO "https://raw.githubusercontent.com/cyberbotics/webots/R2025a/projects/objects/floors/protos/RectangleArena.proto"
EXTERNPROTO "https://raw.githubusercontent.com/cyberbotics/webots/R2025a/projects/robots/kuka/youbot/protos/BodyMesh.proto"
EXTERNPROTO "https://raw.githubusercontent.com/cyberbotics/webots/R2025a/projects/robots/kuka/youbot/protos/Arm0Mesh.proto"
EXTERNPROTO "https://raw.githubusercontent.com/cyberbotics/webots/R2025a/projects/robots/kuka/youbot/protos/Arm1Mesh.proto"
EXTERNPROTO "https://raw.githubusercontent.com/cyberbotics/webots/R2025a/projects/robots/kuka/youbot/protos/Arm2Mesh.proto"
EXTERNPROTO "https://raw.githubusercontent.com/cyberbotics/webots/R2025a/projects/robots/kuka/youbot/protos/Arm3Mesh.proto"
EXTERNPROTO "https://raw.githubusercontent.com/cyberbotics/webots/R2025a/projects/robots/kuka/youbot/protos/Arm4Mesh.proto"
EXTERNPROTO "https://raw.githubusercontent.com/cyberbotics/webots/R2025a/projects/robots/kuka/youbot/protos/Arm5Mesh.proto"
EXTERNPROTO "https://raw.githubusercontent.com/cyberbotics/webots/R2025a/projects/robots/kuka/youbot/protos/FingerMesh.proto"
EXTERNPROTO "https://raw.githubusercontent.com/cyberbotics/webots/R2025a/projects/robots/kuka/youbot/protos/InteriorWheel.proto"
EXTERNPROTO "https://raw.githubusercontent.com/cyberbotics/webots/R2025a/projects/robots/kuka/youbot/protos/ExteriorWheel.proto"
EXTERNPROTO "https://raw.githubusercontent.com/cyberbotics/webots/R2025a/projects/robots/kuka/youbot/protos/PlateMesh.proto"

WorldInfo {
  info [
    "基于YouBot的多目标物自主搜集与定点放置"
    "四角各放置1个彩色木块，机器人需依次抓取并放置到中央桌面"
  ]
  title "YouBot Multi-Target Collection and Placement"
  basicTimeStep 16
  contactProperties [
    ContactProperties {
      material1 "InteriorWheelMat"
      coulombFriction [
        0, 2, 0
      ]
      frictionRotation -0.785398 0
      bounce 0
      forceDependentSlip [
        10, 0
      ]
    }
    ContactProperties {
      material1 "ExteriorWheelMat"
      coulombFriction [
        0, 2, 0
      ]
      frictionRotation 0.785398 0
      bounce 0
      forceDependentSlip [
        10, 0
      ]
    }
  ]
}
Viewpoint {
  orientation 0.19295982917715376 0.4354701420584744 -0.879279397972849 0.9335797940988307
  position -6.7979520196216185 7.263243084742439 2.5607492797293547
  follow "youBot"
}
TexturedBackground {
}
TexturedBackgroundLight {
}
RectangleArena {
  floorSize 10 10
  floorTileSize 1 1
  wallHeight 0.05
}
Solid {
  translation 5.297388390977926e-17 -7.171500510573174e-17 0.6725474997920272
  rotation -0.4235448398338175 0.6466299782340088 -0.6344126731861772 3.7362523384656926e-17
  children [
    Shape {
      appearance PBRAppearance {
        baseColor 0.6 0.4 0.2
        roughness 0.8
        metalness 0
      }
      geometry Box {
        size 1.2 0.8 0.05
      }
    }
    Pose {
      translation -0.55 -0.35 -0.325
      children [
        Shape {
          appearance PBRAppearance {
            baseColor 0.4 0.25 0.1
            roughness 0.9
          }
          geometry Cylinder {
            height 0.7
            radius 0.04
          }
        }
      ]
    }
    Pose {
      translation 0.55 -0.35 -0.325
      children [
        Shape {
          appearance PBRAppearance {
            baseColor 0.4 0.25 0.1
            roughness 0.9
          }
          geometry Cylinder {
            height 0.7
            radius 0.04
          }
        }
      ]
    }
    Pose {
      translation -0.55 0.35 -0.325
      children [
        Shape {
          appearance PBRAppearance {
            baseColor 0.4 0.25 0.1
            roughness 0.9
          }
          geometry Cylinder {
            height 0.7
            radius 0.04
          }
        }
      ]
    }
    Pose {
      translation 0.55 0.35 -0.325
      children [
        Shape {
          appearance PBRAppearance {
            baseColor 0.4 0.25 0.1
            roughness 0.9
          }
          geometry Cylinder {
            height 0.7
            radius 0.04
          }
        }
      ]
    }
  ]
  boundingObject Group {
    children [
      Pose {
        translation 0 0 0.025
        children [
          Box {
            size 1.2 0.8 0.05
          }
        ]
      }
      Pose {
        translation -0.55 -0.35 -0.325
        children [
          Cylinder {
            height 0.7
            radius 0.04
          }
        ]
      }
      Pose {
        translation 0.55 -0.35 -0.325
        children [
          Cylinder {
            height 0.7
            radius 0.04
          }
        ]
      }
      Pose {
        translation -0.55 0.35 -0.325
        children [
          Cylinder {
            height 0.7
            radius 0.04
          }
        ]
      }
      Pose {
        translation 0.55 0.35 -0.325
        children [
          Cylinder {
            height 0.7
            radius 0.04
          }
        ]
      }
    ]
  }
  physics Physics {
    density -1
    mass 50
  }
}
DEF red_block Solid {
  translation -4 4 0.049901900000000096
  rotation -0.9103906009045923 -0.10115451121162274 0.4011941159166131 2.107299201733892e-17
  children [
    Shape {
      appearance PBRAppearance {
        baseColor 1 0 0
        roughness 0.5
      }
      geometry Box {
        size 0.1 0.1 0.1
      }
    }
  ]
  name "red_block"
  boundingObject Box {
    size 0.1 0.1 0.1
  }
  physics Physics {
    density -1
    mass 0.5
  }
  recognitionColors [
    1 0 0
  ]
}
DEF blue_block Solid {
  translation 4 4 0.049901900000000096
  rotation 0.06210454016933928 0.9936726427094296 0.0935826117460582 3.4323226634767986e-17
  children [
    Shape {
      appearance PBRAppearance {
        baseColor 0 0 1
        roughness 0.5
      }
      geometry Box {
        size 0.1 0.1 0.1
      }
    }
  ]
  name "blue_block"
  boundingObject Box {
    size 0.1 0.1 0.1
  }
  physics Physics {
    density -1
    mass 0.5
  }
  recognitionColors [
    0 0 1
  ]
}
DEF green_block Solid {
  translation 4 -4 0.049901900000000096
  rotation 0.06210454016933928 0.9936726427094296 0.0935826117460582 3.4323226634767986e-17
  children [
    Shape {
      appearance PBRAppearance {
        baseColor 0 1 0
        roughness 0.5
      }
      geometry Box {
        size 0.1 0.1 0.1
      }
    }
  ]
  name "green_block"
  boundingObject Box {
    size 0.1 0.1 0.1
  }
  physics Physics {
    density -1
    mass 0.5
  }
  recognitionColors [
    0 1 0
  ]
}
DEF yellow_block Solid {
  translation -4 -4 0.049901900000000096
  rotation 0.06210454016933928 0.9936726427094296 0.0935826117460582 3.4323226634767986e-17
  children [
    Shape {
      appearance PBRAppearance {
        baseColor 1 1 0
        roughness 0.5
      }
      geometry Box {
        size 0.1 0.1 0.1
      }
    }
  ]
  name "yellow_block"
  boundingObject Box {
    size 0.1 0.1 0.1
  }
  physics Physics {
    density -1
    mass 0.5
  }
  recognitionColors [
    1 1 0
  ]
}
DEF youBot Robot {
  translation -3.10567 2.55276 0.10343
  rotation 0.04215918241442637 0.026718588855056367 -0.9987535833966962 -0.03178530717958594
  children [
    BodyMesh {
    }
    Group {
      children [
        Camera {
          translation 0.25 0 0.08
          name "CameraTop"
          fieldOfView 1.064
          width 160
          height 120
          near 0.002
          recognition Recognition {
            maxRange 5
            maxObjects 10
          }
        }
      ]
    }
    Group {
      children [
        Lidar {
          translation 0.25 0 0.15
          name "LidarTop"
          horizontalResolution 360
          fieldOfView 3.14159
          numberOfLayers 1
          maxRange 5
        }
      ]
    }
    DEF ARM Solid {
      translation 0.156 0 0
      children [
        Arm0Mesh {
        }
        HingeJoint {
          jointParameters HingeJointParameters {
            position 1.2814374540705191e-07
            axis 0 0 1
            anchor 0 0 0.077
          }
          device [
            RotationalMotor {
              name "arm1"
              maxVelocity 1.5708
              minPosition -2.9496
              maxPosition 2.9496
              maxTorque 9.5
            }
            PositionSensor {
              name "arm1sensor"
            }
          ]
          endPoint Solid {
            translation 0 0 0.077
            rotation 0 0 1 1.264405455326821e-07
            children [
              Arm1Mesh {
              }
              HingeJoint {
                jointParameters HingeJointParameters {
                  position 1.5700039568903386
                  axis 0 -1 0
                  anchor 0.033 0 0.07
                }
                device [
                  RotationalMotor {
                    name "arm2"
                    maxVelocity 1.5708
                    minPosition -1.13446
                    maxPosition 1.5708
                    maxTorque 15
                  }
                  PositionSensor {
                    name "arm2sensor"
                  }
                ]
                endPoint Solid {
                  translation 0.033 0 0.07
                  rotation 0 -1 0 1.5700039568903388
                  children [
                    Arm2Mesh {
                    }
                    HingeJoint {
                      jointParameters HingeJointParameters {
                        position -2.6350020135196064
                        axis 0 -1 0
                        anchor 0 0 0.155
                      }
                      device [
                        RotationalMotor {
                          name "arm3"
                          maxVelocity 1.5708
                          minPosition -2.63545
                          maxPosition 2.54818
                        }
                        PositionSensor {
                          name "arm3sensor"
                        }
                      ]
                      endPoint Solid {
                        translation 0 0 0.155
                        rotation 0 1 0 2.6350020135196064
                        children [
                          Arm3Mesh {
                          }
                          HingeJoint {
                            jointParameters HingeJointParameters {
                              position 1.7800008879324136
                              axis 0 -1 0
                              anchor 0 0 0.135
                            }
                            device [
                              RotationalMotor {
                                name "arm4"
                                maxVelocity 1.5708
                                minPosition -1.78024
                                maxPosition 1.78024
                              }
                              PositionSensor {
                                name "arm4sensor"
                              }
                            ]
                            endPoint Solid {
                              translation 0 0 0.135
                              rotation 0 -1 0 1.7800008879324136
                              children [
                                Arm4Mesh {
                                }
                                HingeJoint {
                                  jointParameters HingeJointParameters {
                                    position -8.070005710756664e-09
                                    axis 0 0 1
                                    anchor 0 0 0.081
                                  }
                                  device [
                                    RotationalMotor {
                                      name "arm5"
                                      maxVelocity 1.5708
                                      minPosition -2.92343
                                      maxPosition 2.92343
                                      maxTorque 5
                                    }
                                    PositionSensor {
                                      name "arm5sensor"
                                    }
                                  ]
                                  endPoint Solid {
                                    translation 0 0 0.081
                                    children [
                                      Arm5Mesh {
                                      }
                                      SliderJoint {
                                        jointParameters JointParameters {
                                          position 0.06000000001181775
                                          axis 0 1 0
                                        }
                                        device [
                                          LinearMotor {
                                            name "finger::left"
                                            maxPosition 0.060000001763007196
                                            maxForce 100
                                          }
                                          PositionSensor {
                                            name "finger::leftsensor"
                                          }
                                        ]
                                        endPoint Solid {
                                          translation 0 0.06000000001181775 0.09
                                          rotation 1 0 0 4.71239
                                          children [
                                            FingerMesh {
                                            }
                                          ]
                                          name "finger::left"
                                          boundingObject DEF FINGER_BO Group {
                                            children [
                                              Pose {
                                                translation 0 -0.031 0.015
                                                children [
                                                  Box {
                                                    size 0.014 0.032 0.009
                                                  }
                                                ]
                                              }
                                              Pose {
                                                translation 0 -0.007 0.01
                                                children [
                                                  Box {
                                                    size 0.014 0.015 0.019
                                                  }
                                                ]
                                              }
                                            ]
                                          }
                                          physics DEF FINGER_PH Physics {
                                            density -1
                                            mass 0.03
                                            centerOfMass [
                                              0 -0.02 0.01
                                            ]
                                            inertiaMatrix [
                                              6.84034e-06 1.41763e-06 6.40271e-06
                                              0 0 8.29319e-07
                                            ]
                                          }
                                        }
                                      }
                                      SliderJoint {
                                        jointParameters JointParameters {
                                          position 0.05999999998820134
                                          axis 0 -1 0
                                        }
                                        device [
                                          LinearMotor {
                                            name "finger::right"
                                            maxPosition 0.060000001763007196
                                            maxForce 100
                                          }
                                          PositionSensor {
                                            name "finger::rightsensor"
                                          }
                                        ]
                                        endPoint Solid {
                                          translation 0 -0.05999999998820134 0.09
                                          rotation 0 -0.7071067811865476 0.7071067811865476 3.14159
                                          children [
                                            FingerMesh {
                                            }
                                          ]
                                          name "finger::right"
                                          boundingObject USE FINGER_BO
                                          physics USE FINGER_PH
                                        }
                                      }
                                    ]
                                    boundingObject Group {
                                      children [
                                        Pose {
                                          translation 0 0 0.056
                                          children [
                                            Box {
                                              size 0.05 0.095 0.05
                                            }
                                          ]
                                        }
                                        Pose {
                                          translation 0 -0.024 0.003
                                          rotation 1 0 0 -1.5708
                                          children [
                                            Cylinder {
                                              height 0.047
                                              radius 0.027
                                            }
                                          ]
                                        }
                                      ]
                                    }
                                    physics Physics {
                                      density -1
                                      mass 0.877
                                      centerOfMass [
                                        0 0 0.026
                                      ]
                                      inertiaMatrix [
                                        0.00152517 0.00103897 0.000837339
                                        0 0 -0.00015098
                                      ]
                                    }
                                  }
                                }
                              ]
                              boundingObject Pose {
                                translation 0 0.0225 0.065
                                children [
                                  Box {
                                    size 0.06 0.045 0.19
                                  }
                                ]
                              }
                              physics Physics {
                                density -1
                                mass 0.934
                                centerOfMass [
                                  0 0.0225 0.065
                                ]
                                inertiaMatrix [
                                  0.0029674 0.00308998 0.000437812
                                  0 0 -5.99276e-20
                                ]
                              }
                            }
                          }
                        ]
                        boundingObject Pose {
                          translation 0 -0.03 0.078
                          children [
                            Box {
                              size 0.07 0.06 0.21
                            }
                          ]
                        }
                        physics Physics {
                          density -1
                          mass 1.155
                          centerOfMass [
                            0 -0.03 0.078
                          ]
                          inertiaMatrix [
                            0.00459113 0.00471625 0.000818125
                            0 0 1.56701e-20
                          ]
                        }
                      }
                    }
                  ]
                  boundingObject Pose {
                    translation 0.032 0.023 0.07
                    rotation 1 0 0 -1.5708
                    children [
                      Cylinder {
                        height 0.046
                        radius 0.036
                      }
                    ]
                  }
                  physics Physics {
                    density -1
                    mass 2.412
                    centerOfMass [
                      0.015 0.01 0.05
                    ]
                    inertiaMatrix [
                      0.00257923 0.00322484 0.0023115
                      -0.000533052 -0.00082008 -0.00062712
                    ]
                  }
                }
              }
            ]
            boundingObject Pose {
              translation 0 0 0.04
              children [
                Cylinder {
                  height 0.08
                  radius 0.078
                }
              ]
            }
            physics Physics {
              density -1
              mass 0.845
              centerOfMass [
                0 0 0.04
              ]
              inertiaMatrix [
                0.00173591 0.00173591 0.00257049
                0 0 -3.06558e-09
              ]
            }
          }
        }
      ]
      name "front arm"
      boundingObject Pose {
        translation 0 0 0.04
        children [
          Cylinder {
            height 0.08
            radius 0.078
          }
        ]
      }
      physics Physics {
        density -1
        mass 0.845
        centerOfMass [
          0 0 0.04
        ]
        inertiaMatrix [
          0.00173591 0.00173591 0.00257049
          0 0 -3.06558e-09
        ]
      }
    }
    DEF WHEEL1 InteriorWheel {
      translation 0.228 -0.158 -0.055
      anchor 0.228 -0.158 -0.055
      name "wheel1"
      sensorName "wheel1sensor"
    }
    DEF WHEEL2 ExteriorWheel {
      translation 0.228 0.158 -0.055
      anchor 0.228 0.158 -0.055
      name "wheel2"
      sensorName "wheel2sensor"
    }
    DEF WHEEL3 ExteriorWheel {
      translation -0.228 -0.158 -0.055
      anchor -0.228 -0.158 -0.055
      name "wheel3"
      sensorName "wheel3sensor"
    }
    DEF WHEEL4 ExteriorWheel {
      translation -0.228 0.158 -0.055
      anchor -0.228 0.158 -0.055
      name "wheel4"
      sensorName "wheel4sensor"
    }
    DEF PLATE Solid {
      translation -0.155 0 0
      children [
        PlateMesh {
        }
      ]
      name "plate"
      boundingObject Group {
        children [
          Pose {
            translation 0.008 0 0.045
            children [
              Box {
                size 0.25 0.17 0.007
              }
            ]
          }
          Pose {
            translation -0.015 0.112 0.045
            rotation 0 0 1 -0.13
            children [
              Box {
                size 0.17 0.08 0.007
              }
            ]
          }
          Pose {
            translation -0.015 -0.112 0.045
            rotation 0 0 1 0.13
            children [
              Box {
                size 0.17 0.08 0.007
              }
            ]
          }
          Pose {
            translation 0.076 0.084 0.045
            rotation 0 0 1 0.81
            children [
              Box {
                size 0.08 0.08 0.007
              }
            ]
          }
          Pose {
            translation 0.076 -0.084 0.045
            rotation 0 0 1 -0.81
            children [
              Box {
                size 0.08 0.08 0.007
              }
            ]
          }
        ]
      }
      physics Physics {
        density -1
        mass 0.5
      }
    }
  ]
  name "youBot"
  model "KUKA youBot"
  description "KUKA youBot"
  boundingObject Group {
    children [
      Pose {
        translation 0 0 -0.045
        children [
          Box {
            size 0.34 0.34 0.09
          }
        ]
      }
      Pose {
        translation 0 0 -0.045
        children [
          Box {
            size 0.56 0.23 0.09
          }
        ]
      }
    ]
  }
  physics Physics {
    density -1
    mass 22
    centerOfMass [
      0 0 -0.045
    ]
    inertiaMatrix [
      0.166204 0.418086 0.55459
      0 0 0
    ]
  }
  controller "YouBot"
  supervisor TRUE
}
