#VRML_SIM R2025a utf8

EXTERNPROTO "https://raw.githubusercontent.com/cyberbotics/webots/R2025a/projects/objects/backgrounds/protos/TexturedBackground.proto"
EXTERNPROTO "https://raw.githubusercontent.com/cyberbotics/webots/R2025a/projects/objects/backgrounds/protos/TexturedBackgroundLight.proto"
EXTERNPROTO "https://raw.githubusercontent.com/cyberbotics/webots/R2025a/projects/objects/floors/protos/RectangleArena.proto"
EXTERNPROTO "https://raw.githubusercontent.com/cyberbotics/webots/R2025a/projects/robots/kuka/youbot/protos/BodyMesh.proto"
EXTERNPROTO "https://raw.githubusercontent.com/cyberbotics/webots/R2025a/projects/robots/kuka/youbot/protos/Arm0Mesh.proto"
EXTERNPROTO "https://raw.githubusercontent.com/cyberbotics/webots/R2025a/projects/robots/kuka/youbot/protos/Arm1Mesh.proto"
EXTERNPROTO "https://raw.githubusercontent.com/cyberbotics/webots/R2025a/projects/robots/kuka/youbot/protos/Arm2Mesh.proto"
EXTERNPROTO "https://raw.githubusercontent.com/cyberbotics/webots/R2025a/projects/robots/kuka/youbot/protos/Arm3Mesh.proto"
EXTERNPROTO "https://raw.githubusercontent.com/cyberbotics/webots/R2025a/projects/robots/kuka/youbot/protos/Arm4Mesh.proto"
EXTERNPROTO "https://raw.githubusercontent.com/cyberbotics/webots/R2025a/projects/robots/kuka/youbot/protos/Arm5Mesh.proto"
EXTERNPROTO "https://raw.githubusercontent.com/cyberbotics/webots/R2025a/projects/robots/kuka/youbot/protos/FingerMesh.proto"
EXTERNPROTO "https://raw.githubusercontent.com/cyberbotics/webots/R2025a/projects/robots/kuka/youbot/protos/InteriorWheel.proto"
EXTERNPROTO "https://raw.githubusercontent.com/cyberbotics/webots/R2025a/projects/robots/kuka/youbot/protos/ExteriorWheel.proto"
EXTERNPROTO "https://raw.githubusercontent.com/cyberbotics/webots/R2025a/projects/robots/kuka/youbot/protos/PlateMesh.proto"

WorldInfo {
  info [
    "基于YouBot的多目标物自主搜集与定点放置"
    "四角各放置1个彩色木块，机器人需依次抓取并放置到中央桌面"
  ]
  title "YouBot Multi-Target Collection and Placement"
  basicTimeStep 16
  contactProperties [
    ContactProperties {
      material1 "InteriorWheelMat"
      coulombFriction [
        0, 2, 0
      ]
      frictionRotation -0.785398 0
      bounce 0
      forceDependentSlip [
        10, 0
      ]
    }
    ContactProperties {
      material1 "ExteriorWheelMat"
      coulombFriction [
        0, 2, 0
      ]
      frictionRotation 0.785398 0
      bounce 0
      forceDependentSlip [
        10, 0
      ]
    }
  ]
}
Viewpoint {
  orientation 0.016019821749134248 0.028702669276470805 -0.999459615035811 1.0184108756794117
  position -5.055639925099956 6.206419421119188 0.4288159410795621
  follow "youBot"
}
TexturedBackground {
}
TexturedBackgroundLight {
}
RectangleArena {
  floorSize 10 10
  floorTileSize 1 1
  wallHeight 0.05
}
Solid {
  translation 6.1946274745911036e-18 -8.054203235628277e-17 0.4525475003318173
  rotation 0.23084177946955725 -0.8638288169633969 -0.4477854931046188 4.5701443990780607e-17
  children [
    Shape {
      appearance PBRAppearance {
        baseColor 0.6 0.4 0.2
        roughness 0.8
        metalness 0
      }
      geometry Box {
        size 1.2 0.8 0.05
      }
    }
    Pose {
      translation -0.55 -0.35 -0.325
      children [
        Shape {
          appearance PBRAppearance {
            baseColor 0.4 0.25 0.1
            roughness 0.9
          }
          geometry Cylinder {
            height 0.7
            radius 0.04
          }
        }
      ]
    }
    Pose {
      translation 0.55 -0.35 -0.325
      children [
        Shape {
          appearance PBRAppearance {
            baseColor 0.4 0.25 0.1
            roughness 0.9
          }
          geometry Cylinder {
            height 0.7
            radius 0.04
          }
        }
      ]
    }
    Pose {
      translation -0.55 0.35 -0.325
      children [
        Shape {
          appearance PBRAppearance {
            baseColor 0.4 0.25 0.1
            roughness 0.9
          }
          geometry Cylinder {
            height 0.7
            radius 0.04
          }
        }
      ]
    }
    Pose {
      translation 0.55 0.35 -0.325
      children [
        Shape {
          appearance PBRAppearance {
            baseColor 0.4 0.25 0.1
            roughness 0.9
          }
          geometry Cylinder {
            height 0.7
            radius 0.04
          }
        }
      ]
    }
  ]
  boundingObject Group {
    children [
      Pose {
        translation 0 0 0.025
        children [
          Box {
            size 1.2 0.8 0.05
          }
        ]
      }
      Pose {
        translation -0.55 -0.35 -0.325
        children [
          Cylinder {
            height 0.7
            radius 0.04
          }
        ]
      }
      Pose {
        translation 0.55 -0.35 -0.325
        children [
          Cylinder {
            height 0.7
            radius 0.04
          }
        ]
      }
      Pose {
        translation -0.55 0.35 -0.325
        children [
          Cylinder {
            height 0.7
            radius 0.04
          }
        ]
      }
      Pose {
        translation 0.55 0.35 -0.325
        children [
          Cylinder {
            height 0.7
            radius 0.04
          }
        ]
      }
    ]
  }
  physics Physics {
    density -1
    mass 50
  }
  linearVelocity -3.5701346114481854e-17 -6.903624564804908e-18 -5.5468503765662796e-09
  angularVelocity 5.11574482200666e-17 -5.909913816777498e-18 -1.725647578162697e-19
}
DEF red_block Solid {
  translation -4 4 0.04990190009356342
  rotation -0.5253486021448999 0.8405577634318407 0.13217977363750283 4.057549974583085e-17
  children [
    Shape {
      appearance PBRAppearance {
        baseColor 1 0 0
        roughness 0.5
      }
      geometry Box {
        size 0.1 0.1 0.1
      }
    }
  ]
  name "red_block"
  boundingObject Box {
    size 0.1 0.1 0.1
  }
  physics Physics {
    density -1
    mass 0.5
  }
  recognitionColors [
    1 0 0
  ]
}
DEF blue_block Solid {
  translation 4 4 0.04990190009356342
  rotation -0.5253486021448999 0.8405577634318407 0.13217977363750283 4.057549974583085e-17
  children [
    Shape {
      appearance PBRAppearance {
        baseColor 0 0 1
        roughness 0.5
      }
      geometry Box {
        size 0.1 0.1 0.1
      }
    }
  ]
  name "blue_block"
  boundingObject Box {
    size 0.1 0.1 0.1
  }
  physics Physics {
    density -1
    mass 0.5
  }
  recognitionColors [
    0 0 1
  ]
  linearVelocity -1.2544785339989595e-17 -1.2509679436742268e-17 -1.4655150835155767e-09
  angularVelocity 2.664535259100375e-16 -2.6645352591003756e-16 5.192087238674228e-17
}
DEF green_block Solid {
  translation 4 -4 0.04990190009356342
  rotation -0.5253486021448999 0.8405577634318407 0.13217977363750283 4.057549974583085e-17
  children [
    Shape {
      appearance PBRAppearance {
        baseColor 0 1 0
        roughness 0.5
      }
      geometry Box {
        size 0.1 0.1 0.1
      }
    }
  ]
  name "green_block"
  boundingObject Box {
    size 0.1 0.1 0.1
  }
  physics Physics {
    density -1
    mass 0.5
  }
  recognitionColors [
    0 1 0
  ]
  linearVelocity -1.2544785339989595e-17 -1.2509679436742268e-17 -1.4655150835155767e-09
  angularVelocity 2.664535259100375e-16 -2.6645352591003756e-16 5.192087238674228e-17
}
DEF yellow_block Solid {
  translation -4 -4 0.04990190009356342
  rotation -0.5253486021448999 0.8405577634318407 0.13217977363750283 4.057549974583085e-17
  children [
    Shape {
      appearance PBRAppearance {
        baseColor 1 1 0
        roughness 0.5
      }
      geometry Box {
        size 0.1 0.1 0.1
      }
    }
  ]
  name "yellow_block"
  boundingObject Box {
    size 0.1 0.1 0.1
  }
  physics Physics {
    density -1
    mass 0.5
  }
  recognitionColors [
    1 1 0
  ]
  linearVelocity -1.2544785339989595e-17 -1.2509679436742268e-17 -1.4655150835155767e-09
  angularVelocity 2.664535259100375e-16 -2.6645352591003756e-16 5.192087238674228e-17
}
DEF youBot Robot {
  translation -3.615307705842482 3.376393718188927 0.10187832755303756
  rotation -0.0008382193686031285 0.00043950785004286173 0.9999995521104696 2.1269683078159756
  children [
    BodyMesh {
    }
    Group {
      children [
        Camera {
          translation 0.25 0 0.08
          name "CameraTop"
          fieldOfView 1.064
          width 160
          height 120
          near 0.002
          recognition Recognition {
            maxRange 5
            maxObjects 10
          }
        }
      ]
    }
    DEF ARM Solid {
      translation 0.156 0 0
      children [
        Arm0Mesh {
        }
        HingeJoint {
          jointParameters HingeJointParameters {
            position -1.6600114405030003e-06
            axis 0 0 1
            anchor 0 0 0.077
          }
          device [
            RotationalMotor {
              name "arm1"
              maxVelocity 1.5708
              minPosition -2.9496
              maxPosition 2.9496
              maxTorque 9.5
            }
            PositionSensor {
              name "arm1sensor"
            }
          ]
          endPoint Solid {
            translation 0 0 0.077
            rotation 0 0 -0.9999999999999999 1.6601257893092459e-06
            children [
              Arm1Mesh {
              }
              HingeJoint {
                jointParameters HingeJointParameters {
                  position 1.570003873062188
                  axis 0 -1 0
                  anchor 0.033 0 0.07
                }
                device [
                  RotationalMotor {
                    name "arm2"
                    maxVelocity 1.5708
                    minPosition -1.13446
                    maxPosition 1.5708
                    maxTorque 15
                  }
                  PositionSensor {
                    name "arm2sensor"
                  }
                ]
                endPoint Solid {
                  translation 0.033 0 0.07
                  rotation 0 -1 0 1.570003873062188
                  children [
                    Arm2Mesh {
                    }
                    HingeJoint {
                      jointParameters HingeJointParameters {
                        position -2.6350019065983687
                        axis 0 -1 0
                        anchor 0 0 0.155
                      }
                      device [
                        RotationalMotor {
                          name "arm3"
                          maxVelocity 1.5708
                          minPosition -2.63545
                          maxPosition 2.54818
                        }
                        PositionSensor {
                          name "arm3sensor"
                        }
                      ]
                      endPoint Solid {
                        translation 0 0 0.155
                        rotation 0 1 0 2.6350019065983687
                        children [
                          Arm3Mesh {
                          }
                          HingeJoint {
                            jointParameters HingeJointParameters {
                              position 1.7800010532283574
                              axis 0 -1 0
                              anchor 0 0 0.135
                            }
                            device [
                              RotationalMotor {
                                name "arm4"
                                maxVelocity 1.5708
                                minPosition -1.78024
                                maxPosition 1.78024
                              }
                              PositionSensor {
                                name "arm4sensor"
                              }
                            ]
                            endPoint Solid {
                              translation 0 0 0.135
                              rotation 0 -1 0 1.7800010532283574
                              children [
                                Arm4Mesh {
                                }
                                HingeJoint {
                                  jointParameters HingeJointParameters {
                                    position 1.5001922177405428e-07
                                    axis 0 0 1
                                    anchor 0 0 0.081
                                  }
                                  device [
                                    RotationalMotor {
                                      name "arm5"
                                      maxVelocity 1.5708
                                      minPosition -2.92343
                                      maxPosition 2.92343
                                      maxTorque 5
                                    }
                                    PositionSensor {
                                      name "arm5sensor"
                                    }
                                  ]
                                  endPoint Solid {
                                    translation 0 0 0.081
                                    rotation 0 0 1 1.490116119384766e-07
                                    children [
                                      Arm5Mesh {
                                      }
                                      SliderJoint {
                                        jointParameters JointParameters {
                                          position 0.060000001763007196
                                          axis 0 1 0
                                        }
                                        device [
                                          LinearMotor {
                                            name "finger::left"
                                            maxPosition 0.06
                                            maxForce 100
                                          }
                                          PositionSensor {
                                            name "finger::leftsensor"
                                          }
                                        ]
                                        endPoint Solid {
                                          translation 0 0.060000001763007196 0.09
                                          rotation 1 0 0 4.71239
                                          children [
                                            FingerMesh {
                                            }
                                          ]
                                          name "finger::left"
                                          boundingObject DEF FINGER_BO Group {
                                            children [
                                              Pose {
                                                translation 0 -0.031 0.015
                                                children [
                                                  Box {
                                                    size 0.014 0.032 0.009
                                                  }
                                                ]
                                              }
                                              Pose {
                                                translation 0 -0.007 0.01
                                                children [
                                                  Box {
                                                    size 0.014 0.015 0.019
                                                  }
                                                ]
                                              }
                                            ]
                                          }
                                          physics DEF FINGER_PH Physics {
                                            density -1
                                            mass 0.03
                                            centerOfMass [
                                              0 -0.02 0.01
                                            ]
                                            inertiaMatrix [
                                              6.84034e-06 1.41763e-06 6.40271e-06
                                              0 0 8.29319e-07
                                            ]
                                          }
                                          linearVelocity -0.1687409024820158 0.27363043549301186 5.002923095198906e-07
                                          angularVelocity 1.713836152729515e-05 9.924612426727566e-06 -0.0017309277636550517
                                        }
                                      }
                                      SliderJoint {
                                        jointParameters JointParameters {
                                          position 0.06000000173739783
                                          axis 0 -1 0
                                        }
                                        device [
                                          LinearMotor {
                                            name "finger::right"
                                            maxPosition 0.06
                                            maxForce 100
                                          }
                                          PositionSensor {
                                            name "finger::rightsensor"
                                          }
                                        ]
                                        endPoint Solid {
                                          translation 0 -0.06000000173739783 0.09
                                          rotation 0 -0.7071067811865476 0.7071067811865476 3.14159
                                          children [
                                            FingerMesh {
                                            }
                                          ]
                                          name "finger::right"
                                          boundingObject USE FINGER_BO
                                          physics USE FINGER_PH
                                          linearVelocity -0.16861299629221552 0.27342461083224157 5.870642919283941e-07
                                          angularVelocity 1.713835916382955e-05 9.924610936623682e-06 -0.0017309278136895413
                                        }
                                      }
                                    ]
                                    boundingObject Group {
                                      children [
                                        Pose {
                                          translation 0 0 0.056
                                          children [
                                            Box {
                                              size 0.05 0.095 0.05
                                            }
                                          ]
                                        }
                                        Pose {
                                          translation 0 -0.024 0.003
                                          rotation 1 0 0 -1.5708
                                          children [
                                            Cylinder {
                                              height 0.047
                                              radius 0.027
                                            }
                                          ]
                                        }
                                      ]
                                    }
                                    physics Physics {
                                      density -1
                                      mass 0.877
                                      centerOfMass [
                                        0 0 0.026
                                      ]
                                      inertiaMatrix [
                                        0.00152517 0.00103897 0.000837339
                                        0 0 -0.00015098
                                      ]
                                    }
                                    linearVelocity -0.1685967738478822 0.2735788389750966 1.631759530911818e-06
                                    angularVelocity 1.7138342311311252e-05 9.92459769504183e-06 -0.0017309277922845279
                                  }
                                }
                              ]
                              boundingObject Pose {
                                translation 0 0.0225 0.065
                                children [
                                  Box {
                                    size 0.06 0.045 0.19
                                  }
                                ]
                              }
                              physics Physics {
                                density -1
                                mass 0.934
                                centerOfMass [
                                  0 0.0225 0.065
                                ]
                                inertiaMatrix [
                                  0.0029674 0.00308998 0.000437812
                                  0 0 -5.99276e-20
                                ]
                              }
                              linearVelocity -0.16857727316170562 0.2736376123534292 2.1838294870611254e-06
                              angularVelocity 1.6621534983656966e-05 1.075499977290794e-05 -0.0017320581504786273
                            }
                          }
                        ]
                        boundingObject Pose {
                          translation 0 -0.03 0.078
                          children [
                            Box {
                              size 0.07 0.06 0.21
                            }
                          ]
                        }
                        physics Physics {
                          density -1
                          mass 1.155
                          centerOfMass [
                            0 -0.03 0.078
                          ]
                          inertiaMatrix [
                            0.00459113 0.00471625 0.000818125
                            0 0 1.56701e-20
                          ]
                        }
                        linearVelocity -0.16854096078190345 0.27355494824854504 2.0191961859824287e-06
                        angularVelocity 1.661872419671467e-05 1.0753058604334842e-05 -0.0017320588372918197
                      }
                    }
                  ]
                  boundingObject Pose {
                    translation 0.032 0.023 0.07
                    rotation 1 0 0 -1.5708
                    children [
                      Cylinder {
                        height 0.046
                        radius 0.036
                      }
                    ]
                  }
                  physics Physics {
                    density -1
                    mass 2.412
                    centerOfMass [
                      0.015 0.01 0.05
                    ]
                    inertiaMatrix [
                      0.00257923 0.00322484 0.0023115
                      -0.000533052 -0.00082008 -0.00062712
                    ]
                  }
                  linearVelocity -0.16852377833707818 0.2736478236419649 2.759705237155283e-06
                  angularVelocity 1.661213659147435e-05 1.0748646393090642e-05 -0.0017320585494752874
                }
              }
            ]
            boundingObject Pose {
              translation 0 0 0.04
              children [
                Cylinder {
                  height 0.08
                  radius 0.078
                }
              ]
            }
            physics Physics {
              density -1
              mass 0.845
              centerOfMass [
                0 0 0.04
              ]
              inertiaMatrix [
                0.00173591 0.00173591 0.00257049
                0 0 -3.06558e-09
              ]
            }
            linearVelocity -0.16849030745291052 0.27364943317372215 3.09081900325745e-06
            angularVelocity 1.6604738394875485e-05 1.0743709326341786e-05 -0.0017320592979279386
          }
        }
      ]
      name "front arm"
      boundingObject Pose {
        translation 0 0 0.04
        children [
          Cylinder {
            height 0.08
            radius 0.078
          }
        ]
      }
      physics Physics {
        density -1
        mass 0.845
        centerOfMass [
          0 0 0.04
        ]
        inertiaMatrix [
          0.00173591 0.00173591 0.00257049
          0 0 -3.06558e-09
        ]
      }
    }
    DEF WHEEL1 InteriorWheel {
      translation 0.228 -0.158 -0.055
      anchor 0.228 -0.158 -0.055
      name "wheel1"
      sensorName "wheel1sensor"
    }
    DEF WHEEL2 ExteriorWheel {
      translation 0.228 0.158 -0.055
      anchor 0.228 0.158 -0.055
      name "wheel2"
      sensorName "wheel2sensor"
    }
    DEF WHEEL3 ExteriorWheel {
      translation -0.228 -0.158 -0.055
      anchor -0.228 -0.158 -0.055
      name "wheel3"
      sensorName "wheel3sensor"
    }
    DEF WHEEL4 InteriorWheel {
      translation -0.228 0.158 -0.055
      anchor -0.228 0.158 -0.055
      name "wheel4"
      sensorName "wheel4sensor"
    }
    DEF PLATE Solid {
      translation -0.155 0 0
      children [
        PlateMesh {
        }
      ]
      name "plate"
      boundingObject Group {
        children [
          Pose {
            translation 0.008 0 0.045
            children [
              Box {
                size 0.25 0.17 0.007
              }
            ]
          }
          Pose {
            translation -0.015 0.112 0.045
            rotation 0 0 1 -0.13
            children [
              Box {
                size 0.17 0.08 0.007
              }
            ]
          }
          Pose {
            translation -0.015 -0.112 0.045
            rotation 0 0 1 0.13
            children [
              Box {
                size 0.17 0.08 0.007
              }
            ]
          }
          Pose {
            translation 0.076 0.084 0.045
            rotation 0 0 1 0.81
            children [
              Box {
                size 0.08 0.08 0.007
              }
            ]
          }
          Pose {
            translation 0.076 -0.084 0.045
            rotation 0 0 1 -0.81
            children [
              Box {
                size 0.08 0.08 0.007
              }
            ]
          }
        ]
      }
      physics Physics {
        density -1
        mass 0.5
      }
    }
  ]
  name "youBot"
  model "KUKA youBot"
  description "KUKA youBot"
  boundingObject Group {
    children [
      Pose {
        translation 0 0 -0.045
        children [
          Box {
            size 0.34 0.34 0.09
          }
        ]
      }
      Pose {
        translation 0 0 -0.045
        children [
          Box {
            size 0.56 0.23 0.09
          }
        ]
      }
    ]
  }
  physics Physics {
    density -1
    mass 22
    centerOfMass [
      0 0 -0.045
    ]
    inertiaMatrix [
      0.166204 0.418086 0.55459
      0 0 0
    ]
  }
  controller "YouBot"
  supervisor TRUE
  linearVelocity -0.1687159928252429 0.2735129491034868 5.418502085746718e-08
  angularVelocity 1.657486058927939e-05 1.0756938742638448e-05 -0.0017154614698030473
}
